Time: Thu Nov 14 01:56:35 2013; Error information: ['Traceback (most recent call last):\n', '  File "C:\\Users\\Troll\\Documents\\exercises\\TW\\clonned_bot\\request_manager.py", line 131, in unpack_decode\n    decompressed = gzip.decompress(data)\n', '  File "C:\\Python33\\Lib\\gzip.py", line 639, in decompress\n    return f.read()\n', '  File "C:\\Python33\\Lib\\gzip.py", line 360, in read\n    self._read(readsize)\n', '  File "C:\\Python33\\Lib\\gzip.py", line 456, in _read\n    self._read_eof()\n', '  File "C:\\Python33\\Lib\\gzip.py", line 488, in _read_eof\n    crc32 = read32(self.fileobj)\n', '  File "C:\\Python33\\Lib\\gzip.py", line 69, in read32\n    return struct.unpack("<I", input.read(4))[0]\n', 'struct.error: unpack requires a bytes object of length 4\n']
Time: Thu Nov 14 01:56:35 2013; Error information: ['Traceback (most recent call last):\n', '  File "C:\\Users\\Troll\\Documents\\exercises\\TW\\clonned_bot\\attack_management.py", line 73, in cycle\n    self.update_self_state()\n', '  File "C:\\Users\\Troll\\Documents\\exercises\\TW\\clonned_bot\\attack_management.py", line 249, in update_self_state\n    new_reports = self.report_builder.get_new_reports(reports_count)\n', '  File "C:\\Users\\Troll\\Documents\\exercises\\TW\\clonned_bot\\data_management.py", line 36, in get_new_reports\n    reports_page = self.get_reports_page(page)\n', '  File "C:\\Users\\Troll\\Documents\\exercises\\TW\\clonned_bot\\data_management.py", line 56, in get_reports_page\n    reports_page = self.request_manager.get_reports_page(from_page=page*12)\n', '  File "C:\\Users\\Troll\\Documents\\exercises\\TW\\clonned_bot\\request_manager.py", line 79, in get_reports_page\n    return self.safe_opener(req)\n', '  File "C:\\Users\\Troll\\Documents\\exercises\\TW\\clonned_bot\\request_manager.py", line 125, in safe_opener\n    return self.protection_check(self.unpack_decode(data))\n', '  File "C:\\Users\\Troll\\Documents\\exercises\\TW\\clonned_bot\\request_manager.py", line 141, in protection_check\n    match = re.search(bot_ptrn, html_data)\n', '  File "C:\\Python33\\Lib\\re.py", line 161, in search\n    return _compile(pattern, flags).search(string)\n', 'TypeError: expected string or buffer\n']
Time: Thu Nov 14 15:56:38 2013; Error information: ['Traceback (most recent call last):\n', '  File "C:\\Users\\Troll\\Documents\\exercises\\TW\\clonned_bot\\attack_management.py", line 75, in cycle\n    self.update_self_state()\n', '  File "C:\\Users\\Troll\\Documents\\exercises\\TW\\clonned_bot\\attack_management.py", line 251, in update_self_state\n    new_reports = self.report_builder.get_new_reports(reports_count)\n', '  File "C:\\Users\\Troll\\Documents\\exercises\\TW\\clonned_bot\\data_management.py", line 36, in get_new_reports\n    reports_page = self.get_reports_page(page)\n', '  File "C:\\Users\\Troll\\Documents\\exercises\\TW\\clonned_bot\\data_management.py", line 60, in get_reports_page\n    reports_page = match.group()\n', "AttributeError: 'NoneType' object has no attribute 'group'\n"]
Time: Fri Nov 15 07:34:38 2013; Error information: ['Traceback (most recent call last):\n', '  File "C:\\Users\\Troll\\Documents\\exercises\\TW\\clonned_bot\\attack_management.py", line 82, in cycle\n    t_of_attack = self.send_attack(coords, troops)\n', '  File "C:\\Users\\Troll\\Documents\\exercises\\TW\\clonned_bot\\attack_management.py", line 115, in send_attack\n    ch_token = self.get_ch_token(confirm_response)\n', '  File "C:\\Users\\Troll\\Documents\\exercises\\TW\\clonned_bot\\attack_management.py", line 153, in get_ch_token\n    ch_token = (\'ch\', ch_match.group(1))\n', "AttributeError: 'NoneType' object has no attribute 'group'\n"]
Time: Fri Nov 15 07:34:43 2013; Error information: ['Traceback (most recent call last):\n', '  File "C:\\Users\\Troll\\Documents\\exercises\\TW\\clonned_bot\\attack_management.py", line 82, in cycle\n    t_of_attack = self.send_attack(coords, troops)\n', '  File "C:\\Users\\Troll\\Documents\\exercises\\TW\\clonned_bot\\attack_management.py", line 115, in send_attack\n    ch_token = self.get_ch_token(confirm_response)\n', '  File "C:\\Users\\Troll\\Documents\\exercises\\TW\\clonned_bot\\attack_management.py", line 153, in get_ch_token\n    ch_token = (\'ch\', ch_match.group(1))\n', "AttributeError: 'NoneType' object has no attribute 'group'\n"]
Time: Fri Nov 15 07:34:46 2013; Error information: ['Traceback (most recent call last):\n', '  File "C:\\Users\\Troll\\Documents\\exercises\\TW\\clonned_bot\\attack_management.py", line 82, in cycle\n    t_of_attack = self.send_attack(coords, troops)\n', '  File "C:\\Users\\Troll\\Documents\\exercises\\TW\\clonned_bot\\attack_management.py", line 115, in send_attack\n    ch_token = self.get_ch_token(confirm_response)\n', '  File "C:\\Users\\Troll\\Documents\\exercises\\TW\\clonned_bot\\attack_management.py", line 153, in get_ch_token\n    ch_token = (\'ch\', ch_match.group(1))\n', "AttributeError: 'NoneType' object has no attribute 'group'\n"]
Time: Fri Nov 15 07:34:49 2013; Error information: ['Traceback (most recent call last):\n', '  File "C:\\Users\\Troll\\Documents\\exercises\\TW\\clonned_bot\\attack_management.py", line 82, in cycle\n    t_of_attack = self.send_attack(coords, troops)\n', '  File "C:\\Users\\Troll\\Documents\\exercises\\TW\\clonned_bot\\attack_management.py", line 115, in send_attack\n    ch_token = self.get_ch_token(confirm_response)\n', '  File "C:\\Users\\Troll\\Documents\\exercises\\TW\\clonned_bot\\attack_management.py", line 153, in get_ch_token\n    ch_token = (\'ch\', ch_match.group(1))\n', "AttributeError: 'NoneType' object has no attribute 'group'\n"]
Time: Fri Nov 15 07:34:51 2013; Error information: ['Traceback (most recent call last):\n', '  File "C:\\Users\\Troll\\Documents\\exercises\\TW\\clonned_bot\\attack_management.py", line 82, in cycle\n    t_of_attack = self.send_attack(coords, troops)\n', '  File "C:\\Users\\Troll\\Documents\\exercises\\TW\\clonned_bot\\attack_management.py", line 115, in send_attack\n    ch_token = self.get_ch_token(confirm_response)\n', '  File "C:\\Users\\Troll\\Documents\\exercises\\TW\\clonned_bot\\attack_management.py", line 153, in get_ch_token\n    ch_token = (\'ch\', ch_match.group(1))\n', "AttributeError: 'NoneType' object has no attribute 'group'\n"]
Time: Fri Nov 15 07:34:54 2013; Error information: ['Traceback (most recent call last):\n', '  File "C:\\Users\\Troll\\Documents\\exercises\\TW\\clonned_bot\\attack_management.py", line 82, in cycle\n    t_of_attack = self.send_attack(coords, troops)\n', '  File "C:\\Users\\Troll\\Documents\\exercises\\TW\\clonned_bot\\attack_management.py", line 115, in send_attack\n    ch_token = self.get_ch_token(confirm_response)\n', '  File "C:\\Users\\Troll\\Documents\\exercises\\TW\\clonned_bot\\attack_management.py", line 153, in get_ch_token\n    ch_token = (\'ch\', ch_match.group(1))\n', "AttributeError: 'NoneType' object has no attribute 'group'\n"]
Time: Fri Nov 15 07:34:55 2013; Error information: ['Traceback (most recent call last):\n', '  File "C:\\Users\\Troll\\Documents\\exercises\\TW\\clonned_bot\\attack_management.py", line 82, in cycle\n    t_of_attack = self.send_attack(coords, troops)\n', '  File "C:\\Users\\Troll\\Documents\\exercises\\TW\\clonned_bot\\attack_management.py", line 115, in send_attack\n    ch_token = self.get_ch_token(confirm_response)\n', '  File "C:\\Users\\Troll\\Documents\\exercises\\TW\\clonned_bot\\attack_management.py", line 153, in get_ch_token\n    ch_token = (\'ch\', ch_match.group(1))\n', "AttributeError: 'NoneType' object has no attribute 'group'\n"]
Time: Fri Nov 15 07:34:58 2013; Error information: ['Traceback (most recent call last):\n', '  File "C:\\Users\\Troll\\Documents\\exercises\\TW\\clonned_bot\\attack_management.py", line 82, in cycle\n    t_of_attack = self.send_attack(coords, troops)\n', '  File "C:\\Users\\Troll\\Documents\\exercises\\TW\\clonned_bot\\attack_management.py", line 115, in send_attack\n    ch_token = self.get_ch_token(confirm_response)\n', '  File "C:\\Users\\Troll\\Documents\\exercises\\TW\\clonned_bot\\attack_management.py", line 153, in get_ch_token\n    ch_token = (\'ch\', ch_match.group(1))\n', "AttributeError: 'NoneType' object has no attribute 'group'\n"]
Time: Fri Nov 15 07:35:02 2013; Error information: ['Traceback (most recent call last):\n', '  File "C:\\Users\\Troll\\Documents\\exercises\\TW\\clonned_bot\\attack_management.py", line 82, in cycle\n    t_of_attack = self.send_attack(coords, troops)\n', '  File "C:\\Users\\Troll\\Documents\\exercises\\TW\\clonned_bot\\attack_management.py", line 115, in send_attack\n    ch_token = self.get_ch_token(confirm_response)\n', '  File "C:\\Users\\Troll\\Documents\\exercises\\TW\\clonned_bot\\attack_management.py", line 153, in get_ch_token\n    ch_token = (\'ch\', ch_match.group(1))\n', "AttributeError: 'NoneType' object has no attribute 'group'\n"]
Time: Fri Nov 15 07:35:05 2013; Error information: ['Traceback (most recent call last):\n', '  File "C:\\Users\\Troll\\Documents\\exercises\\TW\\clonned_bot\\attack_management.py", line 82, in cycle\n    t_of_attack = self.send_attack(coords, troops)\n', '  File "C:\\Users\\Troll\\Documents\\exercises\\TW\\clonned_bot\\attack_management.py", line 115, in send_attack\n    ch_token = self.get_ch_token(confirm_response)\n', '  File "C:\\Users\\Troll\\Documents\\exercises\\TW\\clonned_bot\\attack_management.py", line 153, in get_ch_token\n    ch_token = (\'ch\', ch_match.group(1))\n', "AttributeError: 'NoneType' object has no attribute 'group'\n"]
Time: Fri Nov 15 07:35:08 2013; Error information: ['Traceback (most recent call last):\n', '  File "C:\\Users\\Troll\\Documents\\exercises\\TW\\clonned_bot\\attack_management.py", line 82, in cycle\n    t_of_attack = self.send_attack(coords, troops)\n', '  File "C:\\Users\\Troll\\Documents\\exercises\\TW\\clonned_bot\\attack_management.py", line 115, in send_attack\n    ch_token = self.get_ch_token(confirm_response)\n', '  File "C:\\Users\\Troll\\Documents\\exercises\\TW\\clonned_bot\\attack_management.py", line 153, in get_ch_token\n    ch_token = (\'ch\', ch_match.group(1))\n', "AttributeError: 'NoneType' object has no attribute 'group'\n"]
Time: Fri Nov 15 07:35:11 2013; Error information: ['Traceback (most recent call last):\n', '  File "C:\\Users\\Troll\\Documents\\exercises\\TW\\clonned_bot\\attack_management.py", line 82, in cycle\n    t_of_attack = self.send_attack(coords, troops)\n', '  File "C:\\Users\\Troll\\Documents\\exercises\\TW\\clonned_bot\\attack_management.py", line 115, in send_attack\n    ch_token = self.get_ch_token(confirm_response)\n', '  File "C:\\Users\\Troll\\Documents\\exercises\\TW\\clonned_bot\\attack_management.py", line 153, in get_ch_token\n    ch_token = (\'ch\', ch_match.group(1))\n', "AttributeError: 'NoneType' object has no attribute 'group'\n"]
Time: Fri Nov 15 07:35:13 2013; Error information: ['Traceback (most recent call last):\n', '  File "C:\\Users\\Troll\\Documents\\exercises\\TW\\clonned_bot\\attack_management.py", line 82, in cycle\n    t_of_attack = self.send_attack(coords, troops)\n', '  File "C:\\Users\\Troll\\Documents\\exercises\\TW\\clonned_bot\\attack_management.py", line 115, in send_attack\n    ch_token = self.get_ch_token(confirm_response)\n', '  File "C:\\Users\\Troll\\Documents\\exercises\\TW\\clonned_bot\\attack_management.py", line 153, in get_ch_token\n    ch_token = (\'ch\', ch_match.group(1))\n', "AttributeError: 'NoneType' object has no attribute 'group'\n"]
Time: Fri Nov 15 07:35:15 2013; Error information: ['Traceback (most recent call last):\n', '  File "C:\\Users\\Troll\\Documents\\exercises\\TW\\clonned_bot\\attack_management.py", line 82, in cycle\n    t_of_attack = self.send_attack(coords, troops)\n', '  File "C:\\Users\\Troll\\Documents\\exercises\\TW\\clonned_bot\\attack_management.py", line 115, in send_attack\n    ch_token = self.get_ch_token(confirm_response)\n', '  File "C:\\Users\\Troll\\Documents\\exercises\\TW\\clonned_bot\\attack_management.py", line 153, in get_ch_token\n    ch_token = (\'ch\', ch_match.group(1))\n', "AttributeError: 'NoneType' object has no attribute 'group'\n"]
Time: Fri Nov 15 07:35:25 2013; Error information: ['Traceback (most recent call last):\n', '  File "C:\\Users\\Troll\\Documents\\exercises\\TW\\clonned_bot\\attack_management.py", line 82, in cycle\n    t_of_attack = self.send_attack(coords, troops)\n', '  File "C:\\Users\\Troll\\Documents\\exercises\\TW\\clonned_bot\\attack_management.py", line 115, in send_attack\n    ch_token = self.get_ch_token(confirm_response)\n', '  File "C:\\Users\\Troll\\Documents\\exercises\\TW\\clonned_bot\\attack_management.py", line 153, in get_ch_token\n    ch_token = (\'ch\', ch_match.group(1))\n', "AttributeError: 'NoneType' object has no attribute 'group'\n"]
Time: Fri Nov 15 08:49:17 2013; Error information: ['Traceback (most recent call last):\n', '  File "C:\\Users\\Troll\\Documents\\exercises\\TW\\clonned_bot\\request_manager.py", line 126, in safe_opener\n    if self.expiration_check(self.unpack_decode(data)):\n', '  File "C:\\Users\\Troll\\Documents\\exercises\\TW\\clonned_bot\\request_manager.py", line 150, in unpack_decode\n    decompressed = gzip.decompress(data)\n', '  File "C:\\Python33\\Lib\\gzip.py", line 639, in decompress\n    return f.read()\n', '  File "C:\\Python33\\Lib\\gzip.py", line 360, in read\n    self._read(readsize)\n', '  File "C:\\Python33\\Lib\\gzip.py", line 456, in _read\n    self._read_eof()\n', '  File "C:\\Python33\\Lib\\gzip.py", line 488, in _read_eof\n    crc32 = read32(self.fileobj)\n', '  File "C:\\Python33\\Lib\\gzip.py", line 69, in read32\n    return struct.unpack("<I", input.read(4))[0]\n', 'struct.error: unpack requires a bytes object of length 4\n']
Time: Fri Nov 15 17:28:13 2013; Error information: ['Traceback (most recent call last):\n', '  File "C:\\Users\\Troll\\Documents\\exercises\\TW\\clonned_bot\\attack_management.py", line 82, in cycle\n    t_of_attack = self.send_attack(coords, troops)\n', '  File "C:\\Users\\Troll\\Documents\\exercises\\TW\\clonned_bot\\attack_management.py", line 115, in send_attack\n    ch_token = self.get_ch_token(confirm_response)\n', '  File "C:\\Users\\Troll\\Documents\\exercises\\TW\\clonned_bot\\attack_management.py", line 153, in get_ch_token\n    ch_token = (\'ch\', ch_match.group(1))\n', "AttributeError: 'NoneType' object has no attribute 'group'\n"]
Unexpected exception: Time: Fri Nov 15 18:15:46 2013; Error information: ['Traceback (most recent call last):\n', '  File "C:\\Python33\\Lib\\urllib\\request.py", line 1248, in do_open\n    h.request(req.get_method(), req.selector, req.data, headers)\n', '  File "C:\\Python33\\Lib\\http\\client.py", line 1061, in request\n    self._send_request(method, url, body, headers)\n', '  File "C:\\Python33\\Lib\\http\\client.py", line 1099, in _send_request\n    self.endheaders(body)\n', '  File "C:\\Python33\\Lib\\http\\client.py", line 1057, in endheaders\n    self._send_output(message_body)\n', '  File "C:\\Python33\\Lib\\http\\client.py", line 902, in _send_output\n    self.send(msg)\n', '  File "C:\\Python33\\Lib\\http\\client.py", line 840, in send\n    self.connect()\n', '  File "C:\\Python33\\Lib\\http\\client.py", line 818, in connect\n    self.timeout, self.source_address)\n', '  File "C:\\Python33\\Lib\\socket.py", line 417, in create_connection\n    for res in getaddrinfo(host, port, 0, SOCK_STREAM):\n', 'socket.gaierror: [Errno 11004] getaddrinfo failed\n', '\nDuring handling of the above exception, another exception occurred:\n\n', 'Traceback (most recent call last):\n', '  File "C:\\Users\\Troll\\Documents\\exercises\\TW\\clonned_bot\\attack_management.py", line 75, in cycle\n    self.update_self_state()\n', '  File "C:\\Users\\Troll\\Documents\\exercises\\TW\\clonned_bot\\attack_management.py", line 257, in update_self_state\n    self.troops_map = self.state_manager.get_troops_map(self.battle_units)\n', '  File "C:\\Users\\Troll\\Documents\\exercises\\TW\\clonned_bot\\village_management.py", line 22, in get_troops_map\n    overview_html = self.request_manager.get_village_overview(self.id)\n', '  File "C:\\Users\\Troll\\Documents\\exercises\\TW\\clonned_bot\\request_manager.py", line 64, in get_village_overview\n    return self.safe_opener(req)\n', '  File "C:\\Users\\Troll\\Documents\\exercises\\TW\\clonned_bot\\request_manager.py", line 124, in safe_opener\n    response = urlopen(request)\n', '  File "C:\\Python33\\Lib\\urllib\\request.py", line 156, in urlopen\n    return opener.open(url, data, timeout)\n', '  File "C:\\Python33\\Lib\\urllib\\request.py", line 469, in open\n    response = self._open(req, data)\n', '  File "C:\\Python33\\Lib\\urllib\\request.py", line 487, in _open\n    \'_open\', req)\n', '  File "C:\\Python33\\Lib\\urllib\\request.py", line 447, in _call_chain\n    result = func(*args)\n', '  File "C:\\Python33\\Lib\\urllib\\request.py", line 1268, in http_open\n    return self.do_open(http.client.HTTPConnection, req)\n', '  File "C:\\Python33\\Lib\\urllib\\request.py", line 1251, in do_open\n    raise URLError(err)\n', 'urllib.error.URLError: <urlopen error [Errno 11004] getaddrinfo failed>\n']
Time: Fri Nov 15 18:24:22 2013; Error information: ['Traceback (most recent call last):\n', '  File "C:\\Users\\Troll\\Documents\\exercises\\TW\\clonned_bot\\request_manager.py", line 126, in safe_opener\n    if self.expiration_check(self.unpack_decode(data)):\n', '  File "C:\\Users\\Troll\\Documents\\exercises\\TW\\clonned_bot\\request_manager.py", line 150, in unpack_decode\n    decompressed = gzip.decompress(data)\n', '  File "C:\\Python33\\Lib\\gzip.py", line 639, in decompress\n    return f.read()\n', '  File "C:\\Python33\\Lib\\gzip.py", line 360, in read\n    self._read(readsize)\n', '  File "C:\\Python33\\Lib\\gzip.py", line 456, in _read\n    self._read_eof()\n', '  File "C:\\Python33\\Lib\\gzip.py", line 488, in _read_eof\n    crc32 = read32(self.fileobj)\n', '  File "C:\\Python33\\Lib\\gzip.py", line 69, in read32\n    return struct.unpack("<I", input.read(4))[0]\n', 'struct.error: unpack requires a bytes object of length 4\n']
Time: Fri Nov 15 19:15:50 2013; Error information: ['Traceback (most recent call last):\n', '  File "C:\\Users\\Troll\\Documents\\exercises\\TW\\clonned_bot\\attack_management.py", line 75, in cycle\n    self.update_self_state()\n', '  File "C:\\Users\\Troll\\Documents\\exercises\\TW\\clonned_bot\\attack_management.py", line 252, in update_self_state\n    self.attack_queue.update_villages(new_reports)\n', '  File "C:\\Users\\Troll\\Documents\\exercises\\TW\\clonned_bot\\attack_management.py", line 414, in update_villages\n    self.villages[coords].update_stats(report)\n', '  File "C:\\Users\\Troll\\Documents\\exercises\\TW\\clonned_bot\\map_management.py", line 242, in update_stats\n    self.looted["total"] += looted\n', "TypeError: unsupported operand type(s) for +=: 'int' and 'NoneType'\n"]
